Workbook
Name Slicer_Status: #N/A
Name Slicer_Vendor: #N/A
Name Slicer_Years: #N/A

Sheet Financial Overview
A1: ACCOUNTS PAYABLE DASHBOARD Reporting Date: 30 July 2025 | U1: KPI | V1: Formula
U2: Total Payable Amount | V2: =SUM(Analysis!G1:G801) -> 2065390.5
U3: Total Outstanding Amount | V3: =SUM(Analysis!J2:J801) -> 669639.14
U8: Outstanding Rate | V8: =V3/V2 -> 0.32421914
U9: DPO | V9: =IFERROR(AVERAGEIFS(Analysis!L2:L801,Analysis!H2:H801,"Paid"),0) -> 30

Sheet Payment Performance
A1: ACCOUNTS PAYABLE DASHBOARD Reporting Date: 30 July 2025 | U1: KPI | V1: Formula
U2: Total Payable Amount | V2: =SUM(Analysis!G1:G801) -> 2065390.5
U3: Total Outstanding Amount | V3: =SUM(Analysis!J2:J801) -> 669639.14
U8: Outstanding Rate | V8: =V3/V2 -> 0.32421914
U9: DPO | V9: =IFERROR(AVERAGEIFS(Analysis!L2:L801,Analysis!H2:H801,"Paid"),0) -> 30

Sheet Pivot Tables
B3: Vendor | C3: Total Invoice Amount | D3: Total Paid Amount | E3: Total Outstanding Amount | G3: Count of Outstanding Invoices | H3: Aging Bucket | M3: Year | N3: Total Invoice Amount | O3: Total Paid Amount | P3: Total Outstanding Amount | R3: Invoice Month | S3: Total Invoice Amount | T3: Total Paid Amount | V3: Invoice Count | W3: Invoice Status | AA3: Vendor | AB3: Avg Overdue Days | AD3: Currency | AE3: Total Outstanding Amount (USD) | AF3: Total Invoice Amount (USD)
B4: BluePrints | C4: 482597.75 | D4: 143243.38 | E4: 145870.6 | G4: Vendor | H4: 1-30 | I4: 31-60 | J4: 61-90 | K4: 90+ | M4: 2023 | N4: 883740.25 | O4: 312998.39 | P4: 240239.87 | R4: Jan 2023 | S4: 50751.98 | T4: 9831.21 | V4: Invoice Date | W4: Open | X4: Paid | Y4: Partial | AA4: Fast Travel | AB4: 287.25899 | AD4: CAD | AE4: 99397.52 | AF4: 280889.18
B5: ABC Supplies | C5: 416980.14 | D5: 119856.74 | E5: 151717.55 | G5: BluePrints | H5: 3 | I5: 5 | J5: 2 | K5: 115 | M5: 2024 | N5: 807803 | O5: 218500.04 | P5: 301256.35 | R5: Feb 2023 | S5: 70146.05 | T5: 23156.8 | V5: 2023 | W5: 93 | X5: 117 | Y5: 114 | AA5: TechMart | AB5: 289.54777 | AD5: AUD | AE5: 87917.81 | AF5: 340277.88
B6: Global Office | C6: 404254.3 | D6: 137555.2 | E6: 129187.87 | G6: Global Office | H6: 4 | I6: 5 | J6: 1 | K6: 100 | M6: 2025 | N6: 373847.28 | O6: 120688.8 | P6: 128142.92 | R6: Mar 2023 | S6: 95504.77 | T6: 30014.77 | V6: 2024 | W6: 123 | X6: 94 | Y6: 108 | AA6: Global Office | AB6: 301.28485 | AD6: EUR | AE6: 129863.13 | AF6: 401129.52
B7: TechMart | C7: 381739.69 | D7: 116472.77 | E7: 124440.23 | G7: ABC Supplies | H7: 5 | J7: 7 | K7: 98 | R7: Apr 2023 | S7: 38272.16 | T7: 15663.53 | V7: 2025 | W7: 51 | X7: 46 | Y7: 54 | AA7: BluePrints | AB7: 309.13736 | AD7: USD | AE7: 142766.69 | AF7: 429911.86
B8: Fast Travel | C8: 379818.65 | D8: 135059.14 | E8: 118422.89 | G8: TechMart | H8: 7 | I8: 3 | J8: 5 | K8: 93 | R8: May 2023 | S8: 90959.29 | T8: 30566.21 | AA8: ABC Supplies | AB8: 325.86624 | AD8: GBP | AE8: 209693.99 | AF8: 613182.09
G9: Fast Travel | H9: 2 | I9: 3 | J9: 5 | K9: 78 | R9: Jun 2023 | S9: 80925.05 | T9: 25616.77 | AA9: Grand Total | AB9: 303.155
R10: Jul 2023 | S10: 75158.73 | T10: 19646.23
R11: Aug 2023 | S11: 77060.44 | T11: 34691.47
R12: Sep 2023 | S12: 65525.11 | T12: 28480.9
R13: Oct 2023 | S13: 57424.7 | T13: 30990.59
R14: Nov 2023 | S14: 75046.4 | T14: 40187.67
R15: Dec 2023 | S15: 106965.57 | T15: 24152.24
R16: Jan 2024 | S16: 72194.02 | T16: 19268.36
R17: Feb 2024 | S17: 51605.53 | T17: 16902.19
R18: Mar 2024 | S18: 57985.35 | T18: 23778.56
R19: Apr 2024 | S19: 87390.35 | T19: 15071.73
R20: May 2024 | S20: 69819.44 | T20: 19885.37
R21: Jun 2024 | S21: 94852.23 | T21: 40788.83
... R33: Jun 2025 | S33: 67192.66 | T33: 20006.05

Sheet Analysis
A1: APID | B1: Vendor | C1: InvoiceDate | D1: InvoiceMonth | E1: DueDate | F1: Currency | G1: Invoice Amount (USD) | H1: Status | I1: Paid Amount (USD) | J1: Outstanding Amount (USD) | K1: PaidDate | L1: Payment day | M1: PaidMonth | N1: Terms | O1: Reference Date | P1: Overdue Days | Q1: Aging | R1: Overdue Status
A2: AP10000 | B2: BluePrints | C2: 45642 | D2: =TEXT(C2,"MMM YYYY") -> Dec 2024 | E2: 45672 | F2: EUR | G2: 400.84 | H2: Open | I2: =IF(H2="Paid",G2,0) -> 0 | J2: =IF(H2="Open",G2,IF(H2="Paid",0,K3/"A")) -> 400.84 | L2: =IF(H2="Paid",K2-C2,"") | M2: =IF(K2="","",TEXT(K2, "YYYY-MMM")) | N2: Net 30 | O2: =MAX(MAX($C$2:$C$801), MAX($E$2:$E$801)) -> 45868 | P2: =IF(K2="", O2-E2,0) -> 196 | Q2: =IF(H2="Paid","Paid", IF(P2<=0,"Current", IF(P2<=30,"1-30", IF(P2<=60,"31-60", IF(P2<=90,"61-90","90+"))))) -> 90+ | R2: =IF(P2=0, "Not Due","Due") -> Due
A3: AP10001 | B3: BluePrints | C3: 45430 | D3: =TEXT(C3,"MMM YYYY") -> May 2024 | E3: 45460 | F3: CAD | G3: 2381.43 | H3: Partial | I3: =IF(H3="Paid",G3,0) -> 0 | J3: =IF(H3="Open",G3,IF(H3="Paid",0,"N/A")) -> N/A | L3: =IF(H3="Paid",K3-C3,"") | M3: =IF(K3="","",TEXT(K3, "YYYY-MMM")) | N3: Net 30 | O3: =MAX(MAX($C$2:$C$801), MAX($E$2:$E$801)) -> 45868 | P3: =IF(K3="", O3-E3,0) -> 408 | Q3: =IF(H3="Paid","Paid", IF(P3<=0,"Current", IF(P3<=30,"1-30", IF(P3<=60,"31-60", IF(P3<=90,"61-90","90+"))))) -> 90+ | R3: =IF(P3=0, "Not Due","Due") -> Due
A4: AP10002 | B4: Fast Travel | C4: 45347 | D4: =TEXT(C4,"MMM YYYY") -> Feb 2024 | E4: 45377 | F4: GBP | G4: 1390.64 | H4: Open | I4: =IF(H4="Paid",G4,0) -> 0 | J4: =IF(H4="Open",G4,IF(H4="Paid",0,"N/A")) -> 1390.64 | L4: =IF(H4="Paid",K4-C4,"") | M4: =IF(K4="","",TEXT(K4, "YYYY-MMM")) | N4: Net 30 | O4: =MAX(MAX($C$2:$C$801), MAX($E$2:$E$801)) -> 45868 | P4: =IF(K4="", O4-E4,0) -> 491 | Q4: =IF(H4="Paid","Paid", IF(P4<=0,"Current", IF(P4<=30,"1-30", IF(P4<=60,"31-60", IF(P4<=90,"61-90","90+"))))) -> 90+ | R4: =IF(P4=0, "Not Due","Due") -> Due
A5: AP10003 | B5: ABC Supplies | C5: 45299 | D5: =TEXT(C5,"MMM YYYY") -> Jan 2024 | E5: 45329 | F5: USD | G5: 4433.05 | H5: Partial | I5: =IF(H5="Paid",G5,0) -> 0 | J5: =IF(H5="Open",G5,IF(H5="Paid",0,"N/A")) -> N/A | L5: =IF(H5="Paid",K5-C5,"") | M5: =IF(K5="","",TEXT(K5, "YYYY-MMM")) | N5: Net 30 | O5: =MAX(MAX($C$2:$C$801), MAX($E$2:$E$801)) -> 45868 | P5: =IF(K5="", O5-E5,0) -> 539 | Q5: =IF(H5="Paid","Paid", IF(P5<=0,"Current", IF(P5<=30,"1-30", IF(P5<=60,"31-60", IF(P5<=90,"61-90","90+"))))) -> 90+ | R5: =IF(P5=0, "Not Due","Due") -> Due
A6: AP10004 | B6: ABC Supplies | C6: 45435 | D6: =TEXT(C6,"MMM YYYY") -> May 2024 | E6: 45465 | F6: GBP | G6: 5904.18 | H6: Partial | I6: =IF(H6="Paid",G6,0) -> 0 | J6: =IF(H6="Open",G6,IF(H6="Paid",0,"N/A")) -> N/A | L6: =IF(H6="Paid",K6-C6,"") | M6: =IF(K6="","",TEXT(K6, "YYYY-MMM")) | N6: Net 30 | O6: =MAX(MAX($C$2:$C$801), MAX($E$2:$E$801)) -> 45868 | P6: =IF(K6="", O6-E6,0) -> 403 | Q6: =IF(H6="Paid","Paid", IF(P6<=0,"Current", IF(P6<=30,"1-30", IF(P6<=60,"31-60", IF(P6<=90,"61-90","90+"))))) -> 90+ | R6: =IF(P6=0, "Not Due","Due") -> Due | U6: Currencies | V6: Exchange Rate
A7: AP10005 | B7: Fast Travel | C7: 45482 | D7: =TEXT(C7,"MMM YYYY") -> Jul 2024 | E7: 45512 | F7: AUD | G7: 1150.93 | H7: Open | I7: =IF(H7="Paid",G7,0) -> 0 | J7: =IF(H7="Open",G7,IF(H7="Paid",0,"N/A")) -> 1150.93 | L7: =IF(H7="Paid",K7-C7,"") | M7: =IF(K7="","",TEXT(K7, "YYYY-MMM")) | N7: Net 30 | O7: =MAX(MAX($C$2:$C$801), MAX($E$2:$E$801)) -> 45868 | P7: =IF(K7="", O7-E7,0) -> 356 | Q7: =IF(H7="Paid","Paid", IF(P7<=0,"Current", IF(P7<=30,"1-30", IF(P7<=60,"31-60", IF(P7<=90,"61-90","90+"))))) -> 90+ | R7: =IF(P7=0, "Not Due","Due") -> Due | U7: EUR/USD | V7: 1.16
A8: AP10006 | B8: BluePrints | C8: 45646 | D8: =TEXT(C8,"MMM YYYY") -> Dec 2024 | E8: 45676 | F8: USD | G8: 894.13 | H8: Open | I8: =IF(H8="Paid",G8,0) -> 0 | J8: =IF(H8="Open",G8,IF(H8="Paid",0,"N/A")) -> 894.13 | L8: =IF(H8="Paid",K8-C8,"") | M8: =IF(K8="","",TEXT(K8, "YYYY-MMM")) | N8: Net 30 | O8: =MAX(MAX($C$2:$C$801), MAX($E$2:$E$801)) -> 45868 | P8: =IF(K8="", O8-E8,0) -> 192 | Q8: =IF(H8="Paid","Paid", IF(P8<=0,"Current", IF(P8<=30,"1-30", IF(P8<=60,"31-60", IF(P8<=90,"61-90","90+"))))) -> 90+ | R8: =IF(P8=0, "Not Due","Due") -> Due | U8: CAD/USD | V8: 0.72
A9: AP10007 | B9: Fast Travel | C9: 45560 | D9: =TEXT(C9,"MMM YYYY") -> Sep 2024 | E9: 45590 | F9: GBP | G9: 1770.6 | H9: Paid | I9: =IF(H9="Paid",G9,0) -> 1770.6 | J9: =IF(H9="Open",G9,IF(H9="Paid",0,"N/A")) -> 0 | K9: 45590 | L9: =IF(H9="Paid",K9-C9,"") -> 30 | M9: =IF(K9="","",TEXT(K9, "YYYY-MMM")) -> 2024-Oct | N9: Net 30 | O9: =MAX(MAX($C$2:$C$801), MAX($E$2:$E$801)) -> 45868 | P9: =IF(K9="", O9-E9,0) -> 0 | Q9: =IF(H9="Paid","Paid", IF(P9<=0,"Current", IF(P9<=30,"1-30", IF(P9<=60,"31-60", IF(P9<=90,"61-90","90+"))))) -> Paid | R9: =IF(P9=0, "Not Due","Due") -> Not Due | U9: GBP/USD | V9: 1.36
A10: AP10008 | B10: ABC Supplies | C10: 45334 | D10: =TEXT(C10,"MMM YYYY") -> Feb 2024 | E10: 45364 | F10: CAD | G10: 2513.86 | H10: Paid | I10: =IF(H10="Paid",G10,0) -> 2513.86 | J10: =IF(H10="Open",G10,IF(H10="Paid",0,"N/A")) -> 0 | K10: 45364 | L10: =IF(H10="Paid",K10-C10,"") -> 30 | M10: =IF(K10="","",TEXT(K10, "YYYY-MMM")) -> 2024-Mar | N10: Net 30 | O10: =MAX(MAX($C$2:$C$801), MAX($E$2:$E$801)) -> 45868 | P10: =IF(K10="", O10-E10,0) -> 0 | Q10: =IF(H10="Paid","Paid", IF(P10<=0,"Current", IF(P10<=30,"1-30", IF(P10<=60,"31-60", IF(P10<=90,"61-90","90+"))))) -> Paid | R10: =IF(P10=0, "Not Due","Due") -> Not Due | U10: AUD/USD | V10: 0.72
A11: AP10009 | B11: ABC Supplies | C11: 45470 | D11: =TEXT(C11,"MMM YYYY") -> Jun 2024 | E11: 45500 | F11: USD | G11: 217.97 | H11: Open | I11: =IF(H11="Paid",G11,0) -> 0 | J11: =IF(H11="Open",G11,IF(H11="Paid",0,"N/A")) -> 217.97 | L11: =IF(H11="Paid",K11-C11,"") | M11: =IF(K11="","",TEXT(K11, "YYYY-MMM")) | N11: Net 30 | O11: =MAX(MAX($C$2:$C$801), MAX($E$2:$E$801)) -> 45868 | P11: =IF(K11="", O11-E11,0) -> 368 | Q11: =IF(H11="Paid","Paid", IF(P11<=0,"Current", IF(P11<=30,"1-30", IF(P11<=60,"31-60", IF(P11<=90,"61-90","90+"))))) -> 90+ | R11: =IF(P11=0, "Not Due","Due") -> Due
A12: AP10010 | B12: BluePrints | C12: 45360 | D12: =TEXT(C12,"MMM YYYY") -> Mar 2024 | E12: 45390 | F12: EUR | G12: 2106.48 | H12: Partial | I12: =IF(H12="Paid",G12,0) -> 0 | J12: =IF(H12="Open",G12,IF(H12="Paid",0,"N/A")) -> N/A | L12: =IF(H12="Paid",K12-C12,"") | M12: =IF(K12="","",TEXT(K12, "YYYY-MMM")) | N12: Net 30 | O12: =MAX(MAX($C$2:$C$801), MAX($E$2:$E$801)) -> 45868 | P12: =IF(K12="", O12-E12,0) -> 478 | Q12: =IF(H12="Paid","Paid", IF(P12<=0,"Current", IF(P12<=30,"1-30", IF(P12<=60,"31-60", IF(P12<=90,"61-90","90+"))))) -> 90+ | R12: =IF(P12=0, "Not Due","Due") -> Due
A13: AP10011 | B13: BluePrints | C13: 45575 | D13: =TEXT(C13,"MMM YYYY") -> Oct 2024 | E13: 45605 | F13: USD | G13: 884.1 | H13: Open | I13: =IF(H13="Paid",G13,0) -> 0 | J13: =IF(H13="Open",G13,IF(H13="Paid",0,"N/A")) -> 884.1 | L13: =IF(H13="Paid",K13-C13,"") | M13: =IF(K13="","",TEXT(K13, "YYYY-MMM")) | N13: Net 30 | O13: =MAX(MAX($C$2:$C$801), MAX($E$2:$E$801)) -> 45868 | P13: =IF(K13="", O13-E13,0) -> 263 | Q13: =IF(H13="Paid","Paid", IF(P13<=0,"Current", IF(P13<=30,"1-30", IF(P13<=60,"31-60", IF(P13<=90,"61-90","90+"))))) -> 90+ | R13: =IF(P13=0, "Not Due","Due") -> Due
A14: AP10012 | B14: ABC Supplies | C14: 45065 | D14: =TEXT(C14,"MMM YYYY") -> May 2023 | E14: 45095 | F14: GBP | G14: 2026.92 | H14: Open | I14: =IF(H14="Paid",G14,0) -> 0 | J14: =IF(H14="Open",G14,IF(H14="Paid",0,"N/A")) -> 2026.92 | L14: =IF(H14="Paid",K14-C14,"") | M14: =IF(K14="","",TEXT(K14, "YYYY-MMM")) | N14: Net 30 | O14: =MAX(MAX($C$2:$C$801), MAX($E$2:$E$801)) -> 45868 | P14: =IF(K14="", O14-E14,0) -> 773 | Q14: =IF(H14="Paid","Paid", IF(P14<=0,"Current", IF(P14<=30,"1-30", IF(P14<=60,"31-60", IF(P14<=90,"61-90","90+"))))) -> 90+ | R14: =IF(P14=0, "Not Due","Due") -> Due
A15: AP10013 | B15: ABC Supplies | C15: 45249 | D15: =TEXT(C15,"MMM YYYY") -> Nov 2023 | E15: 45279 | F15: AUD | G15: 3031.5 | H15: Paid | I15: =IF(H15="Paid",G15,0) -> 3031.5 | J15: =IF(H15="Open",G15,IF(H15="Paid",0,"N/A")) -> 0 | K15: 45279 | L15: =IF(H15="Paid",K15-C15,"") -> 30 | M15: =IF(K15="","",TEXT(K15, "YYYY-MMM")) -> 2023-Dec | N15: Net 30 | O15: =MAX(MAX($C$2:$C$801), MAX($E$2:$E$801)) -> 45868 | P15: =IF(K15="", O15-E15,0) -> 0 | Q15: =IF(H15="Paid","Paid", IF(P15<=0,"Current", IF(P15<=30,"1-30", IF(P15<=60,"31-60", IF(P15<=90,"61-90","90+"))))) -> Paid | R15: =IF(P15=0, "Not Due","Due") -> Not Due
A16: AP10014 | B16: BluePrints | C16: 45417 | D16: =TEXT(C16,"MMM YYYY") -> May 2024 | E16: 45447 | F16: GBP | G16: 2218.68 | H16: Open | I16: =IF(H16="Paid",G16,0) -> 0 | J16: =IF(H16="Open",G16,IF(H16="Paid",0,"N/A")) -> 2218.68 | L16: =IF(H16="Paid",K16-C16,"") | M16: =IF(K16="","",TEXT(K16, "YYYY-MMM")) | N16: Net 30 | O16: =MAX(MAX($C$2:$C$801), MAX($E$2:$E$801)) -> 45868 | P16: =IF(K16="", O16-E16,0) -> 421 | Q16: =IF(H16="Paid","Paid", IF(P16<=0,"Current", IF(P16<=30,"1-30", IF(P16<=60,"31-60", IF(P16<=90,"61-90","90+"))))) -> 90+ | R16: =IF(P16=0, "Not Due","Due") -> Due
A17: AP10015 | B17: BluePrints | C17: 45081 | D17: =TEXT(C17,"MMM YYYY") -> Jun 2023 | E17: 45111 | F17: EUR | G17: 2198 | H17: Paid | I17: =IF(H17="Paid",G17,0) -> 2198 | J17: =IF(H17="Open",G17,IF(H17="Paid",0,"N/A")) -> 0 | K17: 45111 | L17: =IF(H17="Paid",K17-C17,"") -> 30 | M17: =IF(K17="","",TEXT(K17, "YYYY-MMM")) -> 2023-Jul | N17: Net 30 | O17: =MAX(MAX($C$2:$C$801), MAX($E$2:$E$801)) -> 45868 | P17: =IF(K17="", O17-E17,0) -> 0 | Q17: =IF(H17="Paid","Paid", IF(P17<=0,"Current", IF(P17<=30,"1-30", IF(P17<=60,"31-60", IF(P17<=90,"61-90","90+"))))) -> Paid | R17: =IF(P17=0, "Not Due","Due") -> Not Due
A18: AP10016 | B18: BluePrints | C18: 45270 | D18: =TEXT(C18,"MMM YYYY") -> Dec 2023 | E18: 45300 | F18: GBP | G18: 2339.05 | H18: Open | I18: =IF(H18="Paid",G18,0) -> 0 | J18: =IF(H18="Open",G18,IF(H18="Paid",0,"N/A")) -> 2339.05 | L18: =IF(H18="Paid",K18-C18,"") | M18: =IF(K18="","",TEXT(K18, "YYYY-MMM")) | N18: Net 30 | O18: =MAX(MAX($C$2:$C$801), MAX($E$2:$E$801)) -> 45868 | P18: =IF(K18="", O18-E18,0) -> 568 | Q18: =IF(H18="Paid","Paid", IF(P18<=0,"Current", IF(P18<=30,"1-30", IF(P18<=60,"31-60", IF(P18<=90,"61-90","90+"))))) -> 90+ | R18: =IF(P18=0, "Not Due","Due") -> Due
A19: AP10017 | B19: Global Office | C19: 45656 | D19: =TEXT(C19,"MMM YYYY") -> Dec 2024 | E19: 45686 | F19: USD | G19: 2941.63 | H19: Open | I19: =IF(H19="Paid",G19,0) -> 0 | J19: =IF(H19="Open",G19,IF(H19="Paid",0,"N/A")) -> 2941.63 | L19: =IF(H19="Paid",K19-C19,"") | M19: =IF(K19="","",TEXT(K19, "YYYY-MMM")) | N19: Net 30 | O19: =MAX(MAX($C$2:$C$801), MAX($E$2:$E$801)) -> 45868 | P19: =IF(K19="", O19-E19,0) -> 182 | Q19: =IF(H19="Paid","Paid", IF(P19<=0,"Current", IF(P19<=30,"1-30", IF(P19<=60,"31-60", IF(P19<=90,"61-90","90+"))))) -> 90+ | R19: =IF(P19=0, "Not Due","Due") -> Due
A20: AP10018 | B20: Fast Travel | C20: 45470 | D20: =TEXT(C20,"MMM YYYY") -> Jun 2024 | E20: 45500 | F20: USD | G20: 889.44 | H20: Paid | I20: =IF(H20="Paid",G20,0) -> 889.44 | J20: =IF(H20="Open",G20,IF(H20="Paid",0,"N/A")) -> 0 | K20: 45500 | L20: =IF(H20="Paid",K20-C20,"") -> 30 | M20: =IF(K20="","",TEXT(K20, "YYYY-MMM")) -> 2024-Jul | N20: Net 30 | O20: =MAX(MAX($C$2:$C$801), MAX($E$2:$E$801)) -> 45868 | P20: =IF(K20="", O20-E20,0) -> 0 | Q20: =IF(H20="Paid","Paid", IF(P20<=0,"Current", IF(P20<=30,"1-30", IF(P20<=60,"31-60", IF(P20<=90,"61-90","90+"))))) -> Paid | R20: =IF(P20=0, "Not Due","Due") -> Not Due
A21: AP10019 | B21: Fast Travel | C21: 45744 | D21: =TEXT(C21,"MMM YYYY") -> Mar 2025 | E21: 45774 | F21: AUD | G21: 1108 | H21: Partial | I21: =IF(H21="Paid",G21,0) -> 0 | J21: =IF(H21="Open",G21,IF(H21="Paid",0,"N/A")) -> N/A | L21: =IF(H21="Paid",K21-C21,"") | M21: =IF(K21="","",TEXT(K21, "YYYY-MMM")) | N21: Net 30 | O21: =MAX(MAX($C$2:$C$801), MAX($E$2:$E$801)) -> 45868 | P21: =IF(K21="", O21-E21,0) -> 94 | Q21: =IF(H21="Paid","Paid", IF(P21<=0,"Current", IF(P21<=30,"1-30", IF(P21<=60,"31-60", IF(P21<=90,"61-90","90+"))))) -> 90+ | R21: =IF(P21=0, "Not Due","Due") -> Due
A22: AP10020 | B22: TechMart | C22: 45121 | D22: =TEXT(C22,"MMM YYYY") -> Jul 2023 | E22: 45151 | F22: AUD | G22: 717.02 | H22: Open | I22: =IF(H22="Paid",G22,0) -> 0 | J22: =IF(H22="Open",G22,IF(H22="Paid",0,"N/A")) -> 717.02 | L22: =IF(H22="Paid",K22-C22,"") | M22: =IF(K22="","",TEXT(K22, "YYYY-MMM")) | N22: Net 30 | O22: =MAX(MAX($C$2:$C$801), MAX($E$2:$E$801)) -> 45868 | P22: =IF(K22="", O22-E22,0) -> 717 | Q22: =IF(H22="Paid","Paid", IF(P22<=0,"Current", IF(P22<=30,"1-30", IF(P22<=60,"31-60", IF(P22<=90,"61-90","90+"))))) -> 90+ | R22: =IF(P22=0, "Not Due","Due") -> Due
A23: AP10021 | B23: TechMart | C23: 45105 | D23: =TEXT(C23,"MMM YYYY") -> Jun 2023 | E23: 45135 | F23: CAD | G23: 1768.97 | H23: Partial | I23: =IF(H23="Paid",G23,0) -> 0 | J23: =IF(H23="Open",G23,IF(H23="Paid",0,"N/A")) -> N/A | L23: =IF(H23="Paid",K23-C23,"") | M23: =IF(K23="","",TEXT(K23, "YYYY-MMM")) | N23: Net 30 | O23: =MAX(MAX($C$2:$C$801), MAX($E$2:$E$801)) -> 45868 | P23: =IF(K23="", O23-E23,0) -> 733 | Q23: =IF(H23="Paid","Paid", IF(P23<=0,"Current", IF(P23<=30,"1-30", IF(P23<=60,"31-60", IF(P23<=90,"61-90","90+"))))) -> 90+ | R23: =IF(P23=0, "Not Due","Due") -> Due
A24: AP10022 | B24: Global Office | C24: 45653 | D24: =TEXT(C24,"MMM YYYY") -> Dec 2024 | E24: 45683 | F24: CAD | G24: 576.01 | H24: Open | I24: =IF(H24="Paid",G24,0) -> 0 | J24: =IF(H24="Open",G24,IF(H24="Paid",0,"N/A")) -> 576.01 | L24: =IF(H24="Paid",K24-C24,"") | M24: =IF(K24="","",TEXT(K24, "YYYY-MMM")) | N24: Net 30 | O24: =MAX(MAX($C$2:$C$801), MAX($E$2:$E$801)) -> 45868 | P24: =IF(K24="", O24-E24,0) -> 185 | Q24: =IF(H24="Paid","Paid", IF(P24<=0,"Current", IF(P24<=30,"1-30", IF(P24<=60,"31-60", IF(P24<=90,"61-90","90+"))))) -> 90+ | R24: =IF(P24=0, "Not Due","Due") -> Due
A25: AP10023 | B25: BluePrints | C25: 45062 | D25: =TEXT(C25,"MMM YYYY") -> May 2023 | E25: 45092 | F25: GBP | G25: 5758.12 | H25: Partial | I25: =IF(H25="Paid",G25,0) -> 0 | J25: =IF(H25="Open",G25,IF(H25="Paid",0,"N/A")) -> N/A | L25: =IF(H25="Paid",K25-C25,"") | M25: =IF(K25="","",TEXT(K25, "YYYY-MMM")) | N25: Net 30 | O25: =MAX(MAX($C$2:$C$801), MAX($E$2:$E$801)) -> 45868 | P25: =IF(K25="", O25-E25,0) -> 776 | Q25: =IF(H25="Paid","Paid", IF(P25<=0,"Current", IF(P25<=30,"1-30", IF(P25<=60,"31-60", IF(P25<=90,"61-90","90+"))))) -> 90+ | R25: =IF(P25=0, "Not Due","Due") -> Due
A26: AP10024 | B26: Global Office | C26: 45199 | D26: =TEXT(C26,"MMM YYYY") -> Sep 2023 | E26: 45229 | F26: AUD | G26: 478.64 | H26: Open | I26: =IF(H26="Paid",G26,0) -> 0 | J26: =IF(H26="Open",G26,IF(H26="Paid",0,"N/A")) -> 478.64 | L26: =IF(H26="Paid",K26-C26,"") | M26: =IF(K26="","",TEXT(K26, "YYYY-MMM")) | N26: Net 30 | O26: =MAX(MAX($C$2:$C$801), MAX($E$2:$E$801)) -> 45868 | P26: =IF(K26="", O26-E26,0) -> 639 | Q26: =IF(H26="Paid","Paid", IF(P26<=0,"Current", IF(P26<=30,"1-30", IF(P26<=60,"31-60", IF(P26<=90,"61-90","90+"))))) -> 90+ | R26: =IF(P26=0, "Not Due","Due") -> Due
A27: AP10025 | B27: Global Office | C27: 45640 | D27: =TEXT(C27,"MMM YYYY") -> Dec 2024 | E27: 45670 | F27: GBP | G27: 5230.24 | H27: Partial | I27: =IF(H27="Paid",G27,0) -> 0 | J27: =IF(H27="Open",G27,IF(H27="Paid",0,"N/A")) -> N/A | L27: =IF(H27="Paid",K27-C27,"") | M27: =IF(K27="","",TEXT(K27, "YYYY-MMM")) | N27: Net 30 | O27: =MAX(MAX($C$2:$C$801), MAX($E$2:$E$801)) -> 45868 | P27: =IF(K27="", O27-E27,0) -> 198 | Q27: =IF(H27="Paid","Paid", IF(P27<=0,"Current", IF(P27<=30,"1-30", IF(P27<=60,"31-60", IF(P27<=90,"61-90","90+"))))) -> 90+ | R27: =IF(P27=0, "Not Due","Due") -> Due
A28: AP10026 | B28: BluePrints | C28: 45124 | D28: =TEXT(C28,"MMM YYYY") -> Jul 2023 | E28: 45154 | F28: CAD | G28: 3185.38 | H28: Paid | I28: =IF(H28="Paid",G28,0) -> 3185.38 | J28: =IF(H28="Open",G28,IF(H28="Paid",0,"N/A")) -> 0 | K28: 45154 | L28: =IF(H28="Paid",K28-C28,"") -> 30 | M28: =IF(K28="","",TEXT(K28, "YYYY-MMM")) -> 2023-Aug | N28: Net 30 | O28: =MAX(MAX($C$2:$C$801), MAX($E$2:$E$801)) -> 45868 | P28: =IF(K28="", O28-E28,0) -> 0 | Q28: =IF(H28="Paid","Paid", IF(P28<=0,"Current", IF(P28<=30,"1-30", IF(P28<=60,"31-60", IF(P28<=90,"61-90","90+"))))) -> Paid | R28: =IF(P28=0, "Not Due","Due") -> Not Due
A29: AP10027 | B29: Fast Travel | C29: 45376 | D29: =TEXT(C29,"MMM YYYY") -> Mar 2024 | E29: 45406 | F29: USD | G29: 296.65 | H29: Paid | I29: =IF(H29="Paid",G29,0) -> 296.65 | J29: =IF(H29="Open",G29,IF(H29="Paid",0,"N/A")) -> 0 | K29: 45406 | L29: =IF(H29="Paid",K29-C29,"") -> 30 | M29: =IF(K29="","",TEXT(K29, "YYYY-MMM")) -> 2024-Apr | N29: Net 30 | O29: =MAX(MAX($C$2:$C$801), MAX($E$2:$E$801)) -> 45868 | P29: =IF(K29="", O29-E29,0) -> 0 | Q29: =IF(H29="Paid","Paid", IF(P29<=0,"Current", IF(P29<=30,"1-30", IF(P29<=60,"31-60", IF(P29<=90,"61-90","90+"))))) -> Paid | R29: =IF(P29=0, "Not Due","Due") -> Not Due
A30: AP10028 | B30: TechMart | C30: 45593 | D30: =TEXT(C30,"MMM YYYY") -> Oct 2024 | E30: 45623 | F30: GBP | G30: 4212.01 | H30: Open | I30: =IF(H30="Paid",G30,0) -> 0 | J30: =IF(H30="Open",G30,IF(H30="Paid",0,"N/A")) -> 4212.01 | L30: =IF(H30="Paid",K30-C30,"") | M30: =IF(K30="","",TEXT(K30, "YYYY-MMM")) | N30: Net 30 | O30: =MAX(MAX($C$2:$C$801), MAX($E$2:$E$801)) -> 45868 | P30: =IF(K30="", O30-E30,0) -> 245 | Q30: =IF(H30="Paid","Paid", IF(P30<=0,"Current", IF(P30<=30,"1-30", IF(P30<=60,"31-60", IF(P30<=90,"61-90","90+"))))) -> 90+ | R30: =IF(P30=0, "Not Due","Due") -> Due
A31: AP10029 | B31: Global Office | C31: 44991 | D31: =TEXT(C31,"MMM YYYY") -> Mar 2023 | E31: 45021 | F31: CAD | G31: 2893.26 | H31: Open | I31: =IF(H31="Paid",G31,0) -> 0 | J31: =IF(H31="Open",G31,IF(H31="Paid",0,"N/A")) -> 2893.26 | L31: =IF(H31="Paid",K31-C31,"") | M31: =IF(K31="","",TEXT(K31, "YYYY-MMM")) | N31: Net 30 | O31: =MAX(MAX($C$2:$C$801), MAX($E$2:$E$801)) -> 45868 | P31: =IF(K31="", O31-E31,0) -> 847 | Q31: =IF(H31="Paid","Paid", IF(P31<=0,"Current", IF(P31<=30,"1-30", IF(P31<=60,"31-60", IF(P31<=90,"61-90","90+"))))) -> 90+ | R31: =IF(P31=0, "Not Due","Due") -> Due
A32: AP10030 | B32: Fast Travel | C32: 45335 | D32: =TEXT(C32,"MMM YYYY") -> Feb 2024 | E32: 45365 | F32: CAD | G32: 2082.48 | H32: Partial | I32: =IF(H32="Paid",G32,0) -> 0 | J32: =IF(H32="Open",G32,IF(H32="Paid",0,"N/A")) -> N/A | L32: =IF(H32="Paid",K32-C32,"") | M32: =IF(K32="","",TEXT(K32, "YYYY-MMM")) | N32: Net 30 | O32: =MAX(MAX($C$2:$C$801), MAX($E$2:$E$801)) -> 45868 | P32: =IF(K32="", O32-E32,0) -> 503 | Q32: =IF(H32="Paid","Paid", IF(P32<=0,"Current", IF(P32<=30,"1-30", IF(P32<=60,"31-60", IF(P32<=90,"61-90","90+"))))) -> 90+ | R32: =IF(P32=0, "Not Due","Due") -> Due
A33: AP10031 | B33: Fast Travel | C33: 45000 | D33: =TEXT(C33,"MMM YYYY") -> Mar 2023 | E33: 45030 | F33: EUR | G33: 5624.33 | H33: Paid | I33: =IF(H33="Paid",G33,0) -> 5624.33 | J33: =IF(H33="Open",G33,IF(H33="Paid",0,"N/A")) -> 0 | K33: 45030 | L33: =IF(H33="Paid",K33-C33,"") -> 30 | M33: =IF(K33="","",TEXT(K33, "YYYY-MMM")) -> 2023-Apr | N33: Net 30 | O33: =MAX(MAX($C$2:$C$801), MAX($E$2:$E$801)) -> 45868 | P33: =IF(K33="", O33-E33,0) -> 0 | Q33: =IF(H33="Paid","Paid", IF(P33<=0,"Current", IF(P33<=30,"1-30", IF(P33<=60,"31-60", IF(P33<=90,"61-90","90+"))))) -> Paid | R33: =IF(P33=0, "Not Due","Due") -> Not Due
A34: AP10032 | B34: Global Office | C34: 45210 | D34: =TEXT(C34,"MMM YYYY") -> Oct 2023 | E34: 45240 | F34: USD | G34: 4841.22 | H34: Paid | I34: =IF(H34="Paid",G34,0) -> 4841.22 | J34: =IF(H34="Open",G34,IF(H34="Paid",0,"N/A")) -> 0 | K34: 45240 | L34: =IF(H34="Paid",K34-C34,"") -> 30 | M34: =IF(K34="","",TEXT(K34, "YYYY-MMM")) -> 2023-Nov | N34: Net 30 | O34: =MAX(MAX($C$2:$C$801), MAX($E$2:$E$801)) -> 45868 | P34: =IF(K34="", O34-E34,0) -> 0 | Q34: =IF(H34="Paid","Paid", IF(P34<=0,"Current", IF(P34<=30,"1-30", IF(P34<=60,"31-60", IF(P34<=90,"61-90","90+"))))) -> Paid | R34: =IF(P34=0, "Not Due","Due") -> Not Due
A35: AP10033 | B35: ABC Supplies | C35: 45598 | D35: =TEXT(C35,"MMM YYYY") -> Nov 2024 | E35: 45628 | F35: AUD | G35: 2591.76 | H35: Open | I35: =IF(H35="Paid",G35,0) -> 0 | J35: =IF(H35="Open",G35,IF(H35="Paid",0,"N/A")) -> 2591.76 | L35: =IF(H35="Paid",K35-C35,"") | M35: =IF(K35="","",TEXT(K35, "YYYY-MMM")) | N35: Net 30 | O35: =MAX(MAX($C$2:$C$801), MAX($E$2:$E$801)) -> 45868 | P35: =IF(K35="", O35-E35,0) -> 240 | Q35: =IF(H35="Paid","Paid", IF(P35<=0,"Current", IF(P35<=30,"1-30", IF(P35<=60,"31-60", IF(P35<=90,"61-90","90+"))))) -> 90+ | R35: =IF(P35=0, "Not Due","Due") -> Due
A36: AP10034 | B36: Fast Travel | C36: 45668 | D36: =TEXT(C36,"MMM YYYY") -> Jan 2025 | E36: 45698 | F36: GBP | G36: 5317.87 | H36: Paid | I36: =IF(H36="Paid",G36,0) -> 5317.87 | J36: =IF(H36="Open",G36,IF(H36="Paid",0,"N/A")) -> 0 | K36: 45698 | L36: =IF(H36="Paid",K36-C36,"") -> 30 | M36: =IF(K36="","",TEXT(K36, "YYYY-MMM")) -> 2025-Feb | N36: Net 30 | O36: =MAX(MAX($C$2:$C$801), MAX($E$2:$E$801)) -> 45868 | P36: =IF(K36="", O36-E36,0) -> 0 | Q36: =IF(H36="Paid","Paid", IF(P36<=0,"Current", IF(P36<=30,"1-30", IF(P36<=60,"31-60", IF(P36<=90,"61-90","90+"))))) -> Paid | R36: =IF(P36=0, "Not Due","Due") -> Not Due
A37: AP10035 | B37: ABC Supplies | C37: 45025 | D37: =TEXT(C37,"MMM YYYY") -> Apr 2023 | E37: 45055 | F37: CAD | G37: 806.85 | H37: Open | I37: =IF(H37="Paid",G37,0) -> 0 | J37: =IF(H37="Open",G37,IF(H37="Paid",0,"N/A")) -> 806.85 | L37: =IF(H37="Paid",K37-C37,"") | M37: =IF(K37="","",TEXT(K37, "YYYY-MMM")) | N37: Net 30 | O37: =MAX(MAX($C$2:$C$801), MAX($E$2:$E$801)) -> 45868 | P37: =IF(K37="", O37-E37,0) -> 813 | Q37: =IF(H37="Paid","Paid", IF(P37<=0,"Current", IF(P37<=30,"1-30", IF(P37<=60,"31-60", IF(P37<=90,"61-90","90+"))))) -> 90+ | R37: =IF(P37=0, "Not Due","Due") -> Due
A38: AP10036 | B38: BluePrints | C38: 45128 | D38: =TEXT(C38,"MMM YYYY") -> Jul 2023 | E38: 45158 | F38: CAD | G38: 3016.66 | H38: Partial | I38: =IF(H38="Paid",G38,0) -> 0 | J38: =IF(H38="Open",G38,IF(H38="Paid",0,"N/A")) -> N/A | L38: =IF(H38="Paid",K38-C38,"") | M38: =IF(K38="","",TEXT(K38, "YYYY-MMM")) | N38: Net 30 | O38: =MAX(MAX($C$2:$C$801), MAX($E$2:$E$801)) -> 45868 | P38: =IF(K38="", O38-E38,0) -> 710 | Q38: =IF(H38="Paid","Paid", IF(P38<=0,"Current", IF(P38<=30,"1-30", IF(P38<=60,"31-60", IF(P38<=90,"61-90","90+"))))) -> 90+ | R38: =IF(P38=0, "Not Due","Due") -> Due
A39: AP10037 | B39: Global Office | C39: 45504 | D39: =TEXT(C39,"MMM YYYY") -> Jul 2024 | E39: 45534 | F39: USD | G39: 504.02 | H39: Partial | I39: =IF(H39="Paid",G39,0) -> 0 | J39: =IF(H39="Open",G39,IF(H39="Paid",0,"N/A")) -> N/A | L39: =IF(H39="Paid",K39-C39,"") | M39: =IF(K39="","",TEXT(K39, "YYYY-MMM")) | N39: Net 30 | O39: =MAX(MAX($C$2:$C$801), MAX($E$2:$E$801)) -> 45868 | P39: =IF(K39="", O39-E39,0) -> 334 | Q39: =IF(H39="Paid","Paid", IF(P39<=0,"Current", IF(P39<=30,"1-30", IF(P39<=60,"31-60", IF(P39<=90,"61-90","90+"))))) -> 90+ | R39: =IF(P39=0, "Not Due","Due") -> Due
A40: AP10038 | B40: BluePrints | C40: 44934 | D40: =TEXT(C40,"MMM YYYY") -> Jan 2023 | E40: 44964 | F40: GBP | G40: 4288.44 | H40: Open | I40: =IF(H40="Paid",G40,0) -> 0 | J40: =IF(H40="Open",G40,IF(H40="Paid",0,"N/A")) -> 4288.44 | L40: =IF(H40="Paid",K40-C40,"") | M40: =IF(K40="","",TEXT(K40, "YYYY-MMM")) | N40: Net 30 | O40: =MAX(MAX($C$2:$C$801), MAX($E$2:$E$801)) -> 45868 | P40: =IF(K40="", O40-E40,0) -> 904 | Q40: =IF(H40="Paid","Paid", IF(P40<=0,"Current", IF(P40<=30,"1-30", IF(P40<=60,"31-60", IF(P40<=90,"61-90","90+"))))) -> 90+ | R40: =IF(P40=0, "Not Due","Due") -> Due
...

Sheet Raw Data
A1: APID | B1: Vendor | C1: InvoiceDate | D1: DueDate | E1: Amount | F1: Currency | G1: Currency Pair | H1: Invoice Amount (USD) | I1: Status | J1: Outstanding Amount (USD) | K1: PaidDate | L1: Terms
A2: AP10000 | B2: BluePrints | C2: 45642 | D2: 45672 | E2: 344.25 | F2: EUR | G2: ='Raw Data bck'!F2&"/USD" -> EUR/USD | H2: 400.84 | I2: Open | J2: =IF(I2="Open",H2,IF(I2="Paid",0,"N/A")) -> 400.84 | L2: Net 30
A3: AP10001 | B3: BluePrints | C3: 45430 | D3: 45460 | E3: 3298.38 | F3: CAD | G3: ='Raw Data bck'!F3&"/USD" -> CAD/USD | H3: 2381.43 | I3: Partial | J3: =IF(I3="Open",H3,IF(I3="Paid",0,"N/A")) -> N/A | L3: Net 30
A4: AP10002 | B4: Fast Travel | C4: 45347 | D4: 45377 | E4: 1023.43 | F4: GBP | G4: ='Raw Data bck'!F4&"/USD" -> GBP/USD | H4: 1390.64 | I4: Open | J4: =IF(I4="Open",H4,IF(I4="Paid",0,"N/A")) -> 1390.64 | L4: Net 30
A5: AP10003 | B5: ABC Supplies | C5: 45299 | D5: 45329 | E5: 4433.05 | F5: USD | G5: ='Raw Data bck'!F5&"/USD" -> USD/USD | H5: 4433.05 | I5: Partial | J5: =IF(I5="Open",H5,IF(I5="Paid",0,"N/A")) -> N/A | L5: Net 30
A6: AP10004 | B6: ABC Supplies | C6: 45435 | D6: 45465 | E6: 4345.14 | F6: GBP | G6: ='Raw Data bck'!F6&"/USD" -> GBP/USD | H6: 5904.18 | I6: Partial | J6: =IF(I6="Open",H6,IF(I6="Paid",0,"N/A")) -> N/A | L6: Net 30 | N6: Currencies | O6: Exchange Rate
A7: AP10005 | B7: Fast Travel | C7: 45482 | D7: 45512 | E7: 1599.18 | F7: AUD | G7: ='Raw Data bck'!F7&"/USD" -> AUD/USD | H7: 1150.93 | I7: Open | J7: =IF(I7="Open",H7,IF(I7="Paid",0,"N/A")) -> 1150.93 | L7: Net 30 | N7: EUR/USD | O7: 1.16
A8: AP10006 | B8: BluePrints | C8: 45646 | D8: 45676 | E8: 894.13 | F8: USD | G8: ='Raw Data bck'!F8&"/USD" -> USD/USD | H8: 894.13 | I8: Open | J8: =IF(I8="Open",H8,IF(I8="Paid",0,"N/A")) -> 894.13 | L8: Net 30 | N8: CAD/USD | O8: 0.72
A9: AP10007 | B9: Fast Travel | C9: 45560 | D9: 45590 | E9: 1303.06 | F9: GBP | G9: ='Raw Data bck'!F9&"/USD" -> GBP/USD | H9: 1770.6 | I9: Paid | J9: =IF(I9="Open",H9,IF(I9="Paid",0,"N/A")) -> 0 | K9: 45590 | L9: Net 30 | N9: GBP/USD | O9: 1.36
A10: AP10008 | B10: ABC Supplies | C10: 45334 | D10: 45364 | E10: 3481.8 | F10: CAD | G10: ='Raw Data bck'!F10&"/USD" -> CAD/USD | H10: 2513.86 | I10: Paid | J10: =IF(I10="Open",H10,IF(I10="Paid",0,"N/A")) -> 0 | K10: 45364 | L10: Net 30 | N10: AUD/USD | O10: 0.72
A11: AP10009 | B11: ABC Supplies | C11: 45470 | D11: 45500 | E11: 217.97 | F11: USD | G11: ='Raw Data bck'!F11&"/USD" -> USD/USD | H11: 217.97 | I11: Open | J11: =IF(I11="Open",H11,IF(I11="Paid",0,"N/A")) -> 217.97 | L11: Net 30
A12: AP10010 | B12: BluePrints | C12: 45360 | D12: 45390 | E12: 1809.07 | F12: EUR | G12: ='Raw Data bck'!F12&"/USD" -> EUR/USD | H12: 2106.48 | I12: Partial | J12: =IF(I12="Open",H12,IF(I12="Paid",0,"N/A")) -> N/A | L12: Net 30
A13: AP10011 | B13: BluePrints | C13: 45575 | D13: 45605 | E13: 884.1 | F13: USD | G13: ='Raw Data bck'!F13&"/USD" -> USD/USD | H13: 884.1 | I13: Open | J13: =IF(I13="Open",H13,IF(I13="Paid",0,"N/A")) -> 884.1 | L13: Net 30
A14: AP10012 | B14: ABC Supplies | C14: 45065 | D14: 45095 | E14: 1491.7 | F14: GBP | G14: ='Raw Data bck'!F14&"/USD" -> GBP/USD | H14: 2026.92 | I14: Open | J14: =IF(I14="Open",H14,IF(I14="Paid",0,"N/A")) -> 2026.92 | L14: Net 30
A15: AP10013 | B15: ABC Supplies | C15: 45249 | D15: 45279 | E15: 4212.17 | F15: AUD | G15: ='Raw Data bck'!F15&"/USD" -> AUD/USD | H15: 3031.5 | I15: Paid | J15: =IF(I15="Open",H15,IF(I15="Paid",0,"N/A")) -> 0 | K15: 45279 | L15: Net 30
A16: AP10014 | B16: BluePrints | C16: 45417 | D16: 45447 | E16: 1632.82 | F16: GBP | G16: ='Raw Data bck'!F16&"/USD" -> GBP/USD | H16: 2218.68 | I16: Open | J16: =IF(I16="Open",H16,IF(I16="Paid",0,"N/A")) -> 2218.68 | L16: Net 30
A17: AP10015 | B17: BluePrints | C17: 45081 | D17: 45111 | E17: 1887.67 | F17: EUR | G17: ='Raw Data bck'!F17&"/USD" -> EUR/USD | H17: 2198 | I17: Paid | J17: =IF(I17="Open",H17,IF(I17="Paid",0,"N/A")) -> 0 | K17: 45111 | L17: Net 30
A18: AP10016 | B18: BluePrints | C18: 45270 | D18: 45300 | E18: 1721.41 | F18: GBP | G18: ='Raw Data bck'!F18&"/USD" -> GBP/USD | H18: 2339.05 | I18: Open | J18: =IF(I18="Open",H18,IF(I18="Paid",0,"N/A")) -> 2339.05 | L18: Net 30
A19: AP10017 | B19: Global Office | C19: 45656 | D19: 45686 | E19: 2941.63 | F19: USD | G19: ='Raw Data bck'!F19&"/USD" -> USD/USD | H19: 2941.63 | I19: Open | J19: =IF(I19="Open",H19,IF(I19="Paid",0,"N/A")) -> 2941.63 | L19: Net 30
A20: AP10018 | B20: Fast Travel | C20: 45470 | D20: 45500 | E20: 889.44 | F20: USD | G20: ='Raw Data bck'!F20&"/USD" -> USD/USD | H20: 889.44 | I20: Paid | J20: =IF(I20="Open",H20,IF(I20="Paid",0,"N/A")) -> 0 | K20: 45500 | L20: Net 30
A21: AP10019 | B21: Fast Travel | C21: 45744 | D21: 45774 | E21: 1539.53 | F21: AUD | G21: ='Raw Data bck'!F21&"/USD" -> AUD/USD | H21: 1108 | I21: Partial | J21: =IF(I21="Open",H21,IF(I21="Paid",0,"N/A")) -> N/A | L21: Net 30
A22: AP10020 | B22: TechMart | C22: 45121 | D22: 45151 | E22: 996.27 | F22: AUD | G22: ='Raw Data bck'!F22&"/USD" -> AUD/USD | H22: 717.02 | I22: Open | J22: =IF(I22="Open",H22,IF(I22="Paid",0,"N/A")) -> 717.02 | L22: Net 30
A23: AP10021 | B23: TechMart | C23: 45105 | D23: 45135 | E23: 2450.1 | F23: CAD | G23: ='Raw Data bck'!F23&"/USD" -> CAD/USD | H23: 1768.97 | I23: Partial | J23: =IF(I23="Open",H23,IF(I23="Paid",0,"N/A")) -> N/A | L23: Net 30
A24: AP10022 | B24: Global Office | C24: 45653 | D24: 45683 | E24: 797.8 | F24: CAD | G24: ='Raw Data bck'!F24&"/USD" -> CAD/USD | H24: 576.01 | I24: Open | J24: =IF(I24="Open",H24,IF(I24="Paid",0,"N/A")) -> 576.01 | L24: Net 30
A25: AP10023 | B25: BluePrints | C25: 45062 | D25: 45092 | E25: 4237.65 | F25: GBP | G25: ='Raw Data bck'!F25&"/USD" -> GBP/USD | H25: 5758.12 | I25: Partial | J25: =IF(I25="Open",H25,IF(I25="Paid",0,"N/A")) -> N/A | L25: Net 30
A26: AP10024 | B26: Global Office | C26: 45199 | D26: 45229 | E26: 665.06 | F26: AUD | G26: ='Raw Data bck'!F26&"/USD" -> AUD/USD | H26: 478.64 | I26: Open | J26: =IF(I26="Open",H26,IF(I26="Paid",0,"N/A")) -> 478.64 | L26: Net 30
A27: AP10025 | B27: Global Office | C27: 45640 | D27: 45670 | E27: 3849.16 | F27: GBP | G27: ='Raw Data bck'!F27&"/USD" -> GBP/USD | H27: 5230.24 | I27: Partial | J27: =IF(I27="Open",H27,IF(I27="Paid",0,"N/A")) -> N/A | L27: Net 30
A28: AP10026 | B28: BluePrints | C28: 45124 | D28: 45154 | E28: 4411.88 | F28: CAD | G28: ='Raw Data bck'!F28&"/USD" -> CAD/USD | H28: 3185.38 | I28: Paid | J28: =IF(I28="Open",H28,IF(I28="Paid",0,"N/A")) -> 0 | K28: 45154 | L28: Net 30
A29: AP10027 | B29: Fast Travel | C29: 45376 | D29: 45406 | E29: 296.65 | F29: USD | G29: ='Raw Data bck'!F29&"/USD" -> USD/USD | H29: 296.65 | I29: Paid | J29: =IF(I29="Open",H29,IF(I29="Paid",0,"N/A")) -> 0 | K29: 45406 | L29: Net 30
A30: AP10028 | B30: TechMart | C30: 45593 | D30: 45623 | E30: 3099.8 | F30: GBP | G30: ='Raw Data bck'!F30&"/USD" -> GBP/USD | H30: 4212.01 | I30: Open | J30: =IF(I30="Open",H30,IF(I30="Paid",0,"N/A")) -> 4212.01 | L30: Net 30
A31: AP10029 | B31: Global Office | C31: 44991 | D31: 45021 | E31: 4007.29 | F31: CAD | G31: ='Raw Data bck'!F31&"/USD" -> CAD/USD | H31: 2893.26 | I31: Open | J31: =IF(I31="Open",H31,IF(I31="Paid",0,"N/A")) -> 2893.26 | L31: Net 30
A32: AP10030 | B32: Fast Travel | C32: 45335 | D32: 45365 | E32: 2884.32 | F32: CAD | G32: ='Raw Data bck'!F32&"/USD" -> CAD/USD | H32: 2082.48 | I32: Partial | J32: =IF(I32="Open",H32,IF(I32="Paid",0,"N/A")) -> N/A | L32: Net 30
A33: AP10031 | B33: Fast Travel | C33: 45000 | D33: 45030 | E33: 4830.24 | F33: EUR | G33: ='Raw Data bck'!F33&"/USD" -> EUR/USD | H33: 5624.33 | I33: Paid | J33: =IF(I33="Open",H33,IF(I33="Paid",0,"N/A")) -> 0 | K33: 45030 | L33: Net 30
A34: AP10032 | B34: Global Office | C34: 45210 | D34: 45240 | E34: 4841.22 | F34: USD | G34: ='Raw Data bck'!F34&"/USD" -> USD/USD | H34: 4841.22 | I34: Paid | J34: =IF(I34="Open",H34,IF(I34="Paid",0,"N/A")) -> 0 | K34: 45240 | L34: Net 30
A35: AP10033 | B35: ABC Supplies | C35: 45598 | D35: 45628 | E35: 3601.17 | F35: AUD | G35: ='Raw Data bck'!F35&"/USD" -> AUD/USD | H35: 2591.76 | I35: Open | J35: =IF(I35="Open",H35,IF(I35="Paid",0,"N/A")) -> 2591.76 | L35: Net 30
A36: AP10034 | B36: Fast Travel | C36: 45668 | D36: 45698 | E36: 3913.65 | F36: GBP | G36: ='Raw Data bck'!F36&"/USD" -> GBP/USD | H36: 5317.87 | I36: Paid | J36: =IF(I36="Open",H36,IF(I36="Paid",0,"N/A")) -> 0 | K36: 45698 | L36: Net 30
A37: AP10035 | B37: ABC Supplies | C37: 45025 | D37: 45055 | E37: 1117.52 | F37: CAD | G37: ='Raw Data bck'!F37&"/USD" -> CAD/USD | H37: 806.85 | I37: Open | J37: =IF(I37="Open",H37,IF(I37="Paid",0,"N/A")) -> 806.85 | L37: Net 30
A38: AP10036 | B38: BluePrints | C38: 45128 | D38: 45158 | E38: 4178.2 | F38: CAD | G38: ='Raw Data bck'!F38&"/USD" -> CAD/USD | H38: 3016.66 | I38: Partial | J38: =IF(I38="Open",H38,IF(I38="Paid",0,"N/A")) -> N/A | L38: Net 30
A39: AP10037 | B39: Global Office | C39: 45504 | D39: 45534 | E39: 504.02 | F39: USD | G39: ='Raw Data bck'!F39&"/USD" -> USD/USD | H39: 504.02 | I39: Partial | J39: =IF(I39="Open",H39,IF(I39="Paid",0,"N/A")) -> N/A | L39: Net 30
A40: AP10038 | B40: BluePrints | C40: 44934 | D40: 44964 | E40: 3156.05 | F40: GBP | G40: ='Raw Data bck'!F40&"/USD" -> GBP/USD | H40: 4288.44 | I40: Open | J40: =IF(I40="Open",H40,IF(I40="Paid",0,"N/A")) -> 4288.44 | L40: Net 30
...

Sheet Raw Data bck
A1: APID | B1: Vendor | C1: InvoiceDate | D1: DueDate | E1: Amount | F1: Currency | G1: Status | H1: PaidDate | I1: Terms
A2: AP10000 | B2: BluePrints | C2: 45642 | D2: 45672 | E2: 344.25 | F2: EUR | G2: Open | I2: Net 30
A3: AP10001 | B3: BluePrints | C3: 45430 | D3: 45460 | E3: 3298.38 | F3: CAD | G3: Partial | I3: Net 30
A4: AP10002 | B4: Fast Travel | C4: 45347 | D4: 45377 | E4: 1023.43 | F4: GBP | G4: Open | I4: Net 30
A5: AP10003 | B5: ABC Supplies | C5: 45299 | D5: 45329 | E5: 4433.05 | F5: USD | G5: Partial | I5: Net 30
A6: AP10004 | B6: ABC Supplies | C6: 45435 | D6: 45465 | E6: 4345.14 | F6: GBP | G6: Partial | I6: Net 30
A7: AP10005 | B7: Fast Travel | C7: 45482 | D7: 45512 | E7: 1599.18 | F7: AUD | G7: Open | I7: Net 30
A8: AP10006 | B8: BluePrints | C8: 45646 | D8: 45676 | E8: 894.13 | F8: USD | G8: Open | I8: Net 30
A9: AP10007 | B9: Fast Travel | C9: 45560 | D9: 45590 | E9: 1303.06 | F9: GBP | G9: Paid | H9: 45590 | I9: Net 30
A10: AP10008 | B10: ABC Supplies | C10: 45334 | D10: 45364 | E10: 3481.8 | F10: CAD | G10: Paid | H10: 45364 | I10: Net 30
A11: AP10009 | B11: ABC Supplies | C11: 45470 | D11: 45500 | E11: 217.97 | F11: USD | G11: Open | I11: Net 30
A12: AP10010 | B12: BluePrints | C12: 45360 | D12: 45390 | E12: 1809.07 | F12: EUR | G12: Partial | I12: Net 30
A13: AP10011 | B13: BluePrints | C13: 45575 | D13: 45605 | E13: 884.1 | F13: USD | G13: Open | I13: Net 30
A14: AP10012 | B14: ABC Supplies | C14: 45065 | D14: 45095 | E14: 1491.7 | F14: GBP | G14: Open | I14: Net 30
A15: AP10013 | B15: ABC Supplies | C15: 45249 | D15: 45279 | E15: 4212.17 | F15: AUD | G15: Paid | H15: 45279 | I15: Net 30
A16: AP10014 | B16: BluePrints | C16: 45417 | D16: 45447 | E16: 1632.82 | F16: GBP | G16: Open | I16: Net 30
A17: AP10015 | B17: BluePrints | C17: 45081 | D17: 45111 | E17: 1887.67 | F17: EUR | G17: Paid | H17: 45111 | I17: Net 30
A18: AP10016 | B18: BluePrints | C18: 45270 | D18: 45300 | E18: 1721.41 | F18: GBP | G18: Open | I18: Net 30
A19: AP10017 | B19: Global Office | C19: 45656 | D19: 45686 | E19: 2941.63 | F19: USD | G19: Open | I19: Net 30
A20: AP10018 | B20: Fast Travel | C20: 45470 | D20: 45500 | E20: 889.44 | F20: USD | G20: Paid | H20: 45500 | I20: Net 30
A21: AP10019 | B21: Fast Travel | C21: 45744 | D21: 45774 | E21: 1539.53 | F21: AUD | G21: Partial | I21: Net 30
A22: AP10020 | B22: TechMart | C22: 45121 | D22: 45151 | E22: 996.27 | F22: AUD | G22: Open | I22: Net 30
A23: AP10021 | B23: TechMart | C23: 45105 | D23: 45135 | E23: 2450.1 | F23: CAD | G23: Partial | I23: Net 30
A24: AP10022 | B24: Global Office | C24: 45653 | D24: 45683 | E24: 797.8 | F24: CAD | G24: Open | I24: Net 30
A25: AP10023 | B25: BluePrints | C25: 45062 | D25: 45092 | E25: 4237.65 | F25: GBP | G25: Partial | I25: Net 30
A26: AP10024 | B26: Global Office | C26: 45199 | D26: 45229 | E26: 665.06 | F26: AUD | G26: Open | I26: Net 30
A27: AP10025 | B27: Global Office | C27: 45640 | D27: 45670 | E27: 3849.16 | F27: GBP | G27: Partial | I27: Net 30
A28: AP10026 | B28: BluePrints | C28: 45124 | D28: 45154 | E28: 4411.88 | F28: CAD | G28: Paid | H28: 45154 | I28: Net 30
A29: AP10027 | B29: Fast Travel | C29: 45376 | D29: 45406 | E29: 296.65 | F29: USD | G29: Paid | H29: 45406 | I29: Net 30
A30: AP10028 | B30: TechMart | C30: 45593 | D30: 45623 | E30: 3099.8 | F30: GBP | G30: Open | I30: Net 30
A31: AP10029 | B31: Global Office | C31: 44991 | D31: 45021 | E31: 4007.29 | F31: CAD | G31: Open | I31: Net 30
A32: AP10030 | B32: Fast Travel | C32: 45335 | D32: 45365 | E32: 2884.32 | F32: CAD | G32: Partial | I32: Net 30
A33: AP10031 | B33: Fast Travel | C33: 45000 | D33: 45030 | E33: 4830.24 | F33: EUR | G33: Paid | H33: 45030 | I33: Net 30
A34: AP10032 | B34: Global Office | C34: 45210 | D34: 45240 | E34: 4841.22 | F34: USD | G34: Paid | H34: 45240 | I34: Net 30
A35: AP10033 | B35: ABC Supplies | C35: 45598 | D35: 45628 | E35: 3601.17 | F35: AUD | G35: Open | I35: Net 30
A36: AP10034 | B36: Fast Travel | C36: 45668 | D36: 45698 | E36: 3913.65 | F36: GBP | G36: Paid | H36: 45698 | I36: Net 30
A37: AP10035 | B37: ABC Supplies | C37: 45025 | D37: 45055 | E37: 1117.52 | F37: CAD | G37: Open | I37: Net 30
A38: AP10036 | B38: BluePrints | C38: 45128 | D38: 45158 | E38: 4178.2 | F38: CAD | G38: Partial | I38: Net 30
A39: AP10037 | B39: Global Office | C39: 45504 | D39: 45534 | E39: 504.02 | F39: USD | G39: Partial | I39: Net 30
A40: AP10038 | B40: BluePrints | C40: 44934 | D40: 44964 | E40: 3156.05 | F40: GBP | G40: Open | I40: Net 30
...
